Workbook

Sheet Сводка
A1: Отчёт по собеседованию — Java Backend
A2: Автоматическая оценка ответов по эталонам банка вопросов · файл создан 15.10.2026 04:55
A4: Кандидат | B4: Демо-кандидат (пример данных) | F4: ИТОГОВАЯ ОЦЕНКА (из 10)
A5: Дата и время начала | B5: 15.10.2026 04:30 | F5: =B18 -> 7.09
A6: Длительность | B6: 25 мин 0 с
A7: Уровни вопросов | B7: Стажёр, Junior, Middle, Senior
A8: Вопросов | B8: отвечено 50 из 50
A9: Завершение | B9: Полностью — пройден весь список | F9: =IF(F5>=8.5,"Отлично",IF(F5>=7,"Хорошо",IF(F5>=5,"Удовлетворительно",IF(F5>=3,"Слабо","Недостаточно")))) -> Хорошо
A10: Слов сленга (различных) | B10: 1 | C10: релиз
A12: Оценки по критериям (шкала 0–10)
A13: Критерий | B13: Балл | C13: Шкала
A14: Развёрнутость и полнота ответа | B14: =ROUND(AVERAGE('Вопросы'!K2:K51),2) -> 7.01 | C14: =REPT("█",ROUND(B14,0))&REPT("░",10-ROUND(B14,0)) -> ███████░░░
A15: Техническая грамотность | B15: =ROUND(AVERAGE('Вопросы'!L2:L51),2) -> 7.25 | C15: =REPT("█",ROUND(B15,0))&REPT("░",10-ROUND(B15,0)) -> ███████░░░
A16: Владение IT-терминами и сленгом | B16: =ROUND(MIN(10,0.8*AVERAGE('Вопросы'!M2:M51)+2*MIN(1,B10/3)),2) -> 6.86 | C16: =REPT("█",ROUND(B16,0))&REPT("░",10-ROUND(B16,0)) -> ███████░░░
A17: Скорость ответа | B17: =ROUND(AVERAGE('Вопросы'!N2:N51),2) -> 7.24 | C17: =REPT("█",ROUND(B17,0))&REPT("░",10-ROUND(B17,0)) -> ███████░░░
A18: Итог (среднее по 4 критериям) | B18: =ROUND(AVERAGE(B14:B17),2) -> 7.09 | C18: из 10 · среднее четырёх критериев
A20: Резюме
A21: • Итоговая оценка 7.09 из 10 — «Хорошо». Отвечено 50 из 50 вопросов. • Сильнее всего: Git (9.65), Безопасность (9.40). Слабее всего: Observability (0.66), ООП (0.73). • Лучший критерий — техническая грамотность (7.25), самый низкий — IT-термины и сленг (6.86). • Скорость: до начала речи кандидат в среднем думал 6.1 с; темп речи — около 138 слов/мин. • Терминология: использовано 130 различных IT-терминов и 1 слово сленга. • Чаще всего не прозвучало: lock, брокер сообщений, timeout. • Оценка автоматическая и лексическая: она не проверяет правильность сказанного. Решающее слово — за интервьюером.
A29: Результаты по уровням вопросов | F29: Чаще всего не прозвучало
A30: Уровень | B30: Вопросов | C30: Покрытие | D30: Итог | F30: ключевое понятие — в скольких вопросах
A31: Стажёр | B31: =COUNTIF('Вопросы'!$C$2:$C$51,A31) -> 12 | C31: =IFERROR(AVERAGEIFS('Вопросы'!$G$2:$G$51,'Вопросы'!$C$2:$C$51,A31),0) -> 0.7606189 | D31: =IFERROR(AVERAGEIFS('Вопросы'!$O$2:$O$51,'Вопросы'!$C$2:$C$51,A31),0) -> 7.52 | F31: lock — 3
A32: Junior | B32: =COUNTIF('Вопросы'!$C$2:$C$51,A32) -> 14 | C32: =IFERROR(AVERAGEIFS('Вопросы'!$G$2:$G$51,'Вопросы'!$C$2:$C$51,A32),0) -> 0.73383554 | D32: =IFERROR(AVERAGEIFS('Вопросы'!$O$2:$O$51,'Вопросы'!$C$2:$C$51,A32),0) -> 7.23 | F32: брокер сообщений — 3
A33: Middle | B33: =COUNTIF('Вопросы'!$C$2:$C$51,A33) -> 13 | C33: =IFERROR(AVERAGEIFS('Вопросы'!$G$2:$G$51,'Вопросы'!$C$2:$C$51,A33),0) -> 0.64937414 | D33: =IFERROR(AVERAGEIFS('Вопросы'!$O$2:$O$51,'Вопросы'!$C$2:$C$51,A33),0) -> 6.81 | F33: timeout — 2
A34: Senior | B34: =COUNTIF('Вопросы'!$C$2:$C$51,A34) -> 11 | C34: =IFERROR(AVERAGEIFS('Вопросы'!$G$2:$G$51,'Вопросы'!$C$2:$C$51,A34),0) -> 0.80196635 | D34: =IFERROR(AVERAGEIFS('Вопросы'!$O$2:$O$51,'Вопросы'!$C$2:$C$51,A34),0) -> 7.78 | F34: trace — 2
F35: атомарность — 2
F36: API — 1
F37: Callable — 1
F38: CompletableFuture — 1
A40: Результаты по темам (от слабых к сильным)
A41: Тема | B41: Вопросов | C41: Покрытие | D41: Итог
A42: Observability | B42: =COUNTIF('Вопросы'!$D$2:$D$51,A42) -> 1 | C42: =IFERROR(AVERAGEIFS('Вопросы'!$G$2:$G$51,'Вопросы'!$D$2:$D$51,A42),0) -> 0 | D42: =IFERROR(AVERAGEIFS('Вопросы'!$O$2:$O$51,'Вопросы'!$D$2:$D$51,A42),0) -> 0.66
A43: ООП | B43: =COUNTIF('Вопросы'!$D$2:$D$51,A43) -> 1 | C43: =IFERROR(AVERAGEIFS('Вопросы'!$G$2:$G$51,'Вопросы'!$D$2:$D$51,A43),0) -> 0 | D43: =IFERROR(AVERAGEIFS('Вопросы'!$O$2:$O$51,'Вопросы'!$D$2:$D$51,A43),0) -> 0.73
A44: Spring Boot | B44: =COUNTIF('Вопросы'!$D$2:$D$51,A44) -> 1 | C44: =IFERROR(AVERAGEIFS('Вопросы'!$G$2:$G$51,'Вопросы'!$D$2:$D$51,A44),0) -> 0 | D44: =IFERROR(AVERAGEIFS('Вопросы'!$O$2:$O$51,'Вопросы'!$D$2:$D$51,A44),0) -> 0.75
A45: Многопоточность | B45: =COUNTIF('Вопросы'!$D$2:$D$51,A45) -> 3 | C45: =IFERROR(AVERAGEIFS('Вопросы'!$G$2:$G$51,'Вопросы'!$D$2:$D$51,A45),0) -> 0.28045985 | D45: =IFERROR(AVERAGEIFS('Вопросы'!$O$2:$O$51,'Вопросы'!$D$2:$D$51,A45),0) -> 3.37
A46: Базы данных | B46: =COUNTIF('Вопросы'!$D$2:$D$51,A46) -> 2 | C46: =IFERROR(AVERAGEIFS('Вопросы'!$G$2:$G$51,'Вопросы'!$D$2:$D$51,A46),0) -> 0.27773496 | D46: =IFERROR(AVERAGEIFS('Вопросы'!$O$2:$O$51,'Вопросы'!$D$2:$D$51,A46),0) -> 3.9
A47: Тестирование | B47: =COUNTIF('Вопросы'!$D$2:$D$51,A47) -> 3 | C47: =IFERROR(AVERAGEIFS('Вопросы'!$G$2:$G$51,'Вопросы'!$D$2:$D$51,A47),0) -> 0.66666667 | D47: =IFERROR(AVERAGEIFS('Вопросы'!$O$2:$O$51,'Вопросы'!$D$2:$D$51,A47),0) -> 6.05
A48: Распределённые системы | B48: =COUNTIF('Вопросы'!$D$2:$D$51,A48) -> 3 | C48: =IFERROR(AVERAGEIFS('Вопросы'!$G$2:$G$51,'Вопросы'!$D$2:$D$51,A48),0) -> 0.66666667 | D48: =IFERROR(AVERAGEIFS('Вопросы'!$O$2:$O$51,'Вопросы'!$D$2:$D$51,A48),0) -> 6.56
A49: SQL | B49: =COUNTIF('Вопросы'!$D$2:$D$51,A49) -> 4 | C49: =IFERROR(AVERAGEIFS('Вопросы'!$G$2:$G$51,'Вопросы'!$D$2:$D$51,A49),0) -> 0.65390776 | D49: =IFERROR(AVERAGEIFS('Вопросы'!$O$2:$O$51,'Вопросы'!$D$2:$D$51,A49),0) -> 6.9
A50: Java Core | B50: =COUNTIF('Вопросы'!$D$2:$D$51,A50) -> 6 | C50: =IFERROR(AVERAGEIFS('Вопросы'!$G$2:$G$51,'Вопросы'!$D$2:$D$51,A50),0) -> 0.76317926 | D50: =IFERROR(AVERAGEIFS('Вопросы'!$O$2:$O$51,'Вопросы'!$D$2:$D$51,A50),0) -> 7.52
A51: JVM | B51: =COUNTIF('Вопросы'!$D$2:$D$51,A51) -> 2 | C51: =IFERROR(AVERAGEIFS('Вопросы'!$G$2:$G$51,'Вопросы'!$D$2:$D$51,A51),0) -> 0.8191295 | D51: =IFERROR(AVERAGEIFS('Вопросы'!$O$2:$O$51,'Вопросы'!$D$2:$D$51,A51),0) -> 8.44
...

Sheet Вопросы
A1: № | B1: Вопрос | C1: Уровень | D1: Тема | E1: Ответ кандидата | F1: Уточнения: вопрос → ответ | G1: Покрытие эталона | H1: Прозвучало (★ — ядро) | I1: Не прозвучало (★ — ядро) | J1: IT-термины и сленг | K1: Полнота | L1: Техника | M1: Термины | N1: Скорость | O1: Итог по вопросу | P1: Комментарий системы
A2: 1 | B2: Что такое JVM, JRE и JDK? | C2: Стажёр | D2: Java Core | E2: ну JVM — виртуальная машина, исполняющая байткод Java. JRE — среда для запуска приложений (JVM и библиотеки выполнения; в современных поставках JDK отдельный JRE обычно не распространяется). JDK включает инструменты разработки, в том числе компилятор javac, и среду выполнения. | F2: — | G2: 1 | H2: ★ javac, ★ байткод, ★ среда, ★ библиотеки, ★ поставках, ★ распространяется, ★ включает, ★ исполняющая, современных, разработки … и ещё 8 (см. лист «Понятия») | I2: — | J2: JVM, байткод, Java, JRE, JDK, javac | K2: 9.4148936 | L2: 9.4444444 | M2: 10 | N2: 8.4213333 | O2: =ROUND(AVERAGE(K2:N2),2) -> 9.32 | P2: Итог: ответ достаточный — ключевые понятия названы
A3: 2 | B3: Чем отличаются примитивные типы от ссылочных? | C3: Стажёр | D3: Java Core | E3: Примитивные переменные хранят значения примитивного типа, например int или boolean. Ссылочные переменные содержат ссылку на объект | F3: Уточнение 1: Что произойдёт при распаковке null из Integer? → либо null. Объекты создаются в куче в рамках модели памяти JVM; детали размещения могут оптимизироваться JVM. | G3: 1 | H3: ★ int, ★ JVM, ★ модель памяти, ★ ссылка, ★ heap, ★ хранят, рамках, размещения, переменные, создаются … и ещё 4 (см. лист «Понятия») | I3: — | J3: int, ссылка, heap, модель памяти, JVM | K3: 9.4047619 | L3: 9.375 | M3: 10 | N3: 7.5225 | O3: =ROUND(AVERAGE(K3:N3),2) -> 9.08 | P3: Итог: ответ достаточный — ключевые понятия названы; уточняющих вопросов: 1; долго начинал отвечать (8.5 с)
A4: 3 | B4: Назовите четыре основных принципа ООП. | C4: Стажёр | D4: ООП | E4: ну не знаю вроде как бы | F4: — | G4: 0 | H4: — | I4: ★ инкапсуляция, ★ полиморфизм, ★ абстракция, ★ интерфейс, ★ наследование, ★ выделение, ★ существенных, свойств, основе, разных … и ещё 6 (см. лист «Понятия») | J4: — | K4: 0.48387097 | L4: 0 | M4: 0 | N4: 2.4532 | O4: =ROUND(AVERAGE(K4:N4),2) -> 0.73 | P4: Итог: кандидат сказал, что не знает — не давили; сказал, что не знает
A5: 4 | B5: Чем отличаются == и equals()? | C5: Стажёр | D5: Java Core | E5: Для примитивов == сравнивает значения. Для ссылок == проверяет идентичность ссылок, то | F5: Уточнение 1: Что будет с equals() у String и почему строки сравнивают именно так? → на один объект. equals() сравнивает логическое равенство согласно реализации Object.equals() по умолчанию эквивалентен сравнению ссылок. | G5: 0.95391534 | H5: ★ Object, ★ int, ★ ссылок, ★ эквивалентен, ★ сравнить, логическое, равенство, умолчанию, сравнении, идентичность | I5: указывают | J5: int, equals, Object | K5: 8.779365 | L5: 9.930873 | M5: 10 | N5: 8.9916667 | O5: =ROUND(AVERAGE(K5:N5),2) -> 9.43 | P5: Итог: ответ достаточный — ключевые понятия названы; уточняющих вопросов: 1
A6: 5 | B6: Чем отличаются List, Set и Map? | C6: Стажёр | D6: Коллекции | E6: ну List хранит упорядоченную последовательность и допускает дубликаты; Set моделирует множество уникальных элементов; Map хранит пары ключ-значение с уникальными ключами. Map не является подтипом Collection. | F6: — | G6: 1 | H6: ★ коллекции, ★ упорядоченную, ★ дубликаты, ★ элементов, подтипом, последовательность, допускает, моделирует, хранит, уникальных | I6: — | J6: List, Set, Map, коллекции | K6: 9.469697 | L6: 9.2307692 | M6: 10 | N6: 7.9306667 | O6: =ROUND(AVERAGE(K6:N6),2) -> 9.16 | P6: Итог: ответ достаточный — ключевые понятия названы
A7: 6 | B7: Чем checked-исключения отличаются от unchecked? | C7: Стажёр | D7: Исключения | E7: ну Checked-исключения должны быть обработаны или объявлены в throws на этапе компиляции. RuntimeException и её подклассы — unchecked; компилятор не требует их явно обрабатывать. Выбор зависит от контракта API и возможности вызывающего кода восстановиться. | F7: — | G7: 0.93272016 | H7: ★ throws, ★ API, ★ объявлены, ★ подклассы, ★ требует, вызывающего, компилятор, обрабатывать, этапе, восстановиться | I7: runtimeexception | J7: checked, исключение, throws, unchecked, API | K7: 8.9721454 | L7: 9.3167814 | M7: 10 | N7: 9.6683333 | O7: =ROUND(AVERAGE(K7:N7),2) -> 9.49 | P7: Итог: ответ достаточный — ключевые понятия названы
A8: 7 | B8: Для чего нужны static, final и finally? | C8: Стажёр | D8: Java Core | E8: static относится к члену класса, а не конкретному экземпляру; final запрещает повторное присваивание переменной, переопределение метода или наследование класса | F8: — | G8: 0.6251602 | H8: ★ переопределение, ★ наследование, ★ retry, ★ относится, члену, запрещает, присваивание, переменные, экземпляру, конкретному | I8: ★ throws, ★ try-with-resources, предпочтительнее, завершающих | J8: static, final, retry, переопределение, наследование | K8: 5.6200741 | L8: 6.7415204 | M8: 10 | N8: 7.1796667 | O8: =ROUND(AVERAGE(K8:N8),2) -> 7.39 | P8: Итог: ответ достаточный — ключевые понятия названы; долго начинал отвечать (10.0 с)
A9: 8 | B9: Что такое первичный и внешний ключ? | C9: Стажёр | D9: SQL | E9: ну не знаю вроде как бы | F9: — | G9: 0 | H9: — | I9: ★ первичный ключ, ★ String, ★ однозначно, ★ задает, ★ целостность, ссылочных, таблицы, идентичность, допускает, null … и ещё 2 (см. лист «Понятия») | J9: — | K9: 0.44117647 | L9: 0 | M9: 0 | N9: 2.2193 | O9: =ROUND(AVERAGE(K9:N9),2) -> 0.67 | P9: Итог: кандидат сказал, что не знает — не давили; долго начинал отвечать (9.3 с); сказал, что не знает
A10: 9 | B10: Чем отличаются WHERE и HAVING? | C10: Стажёр | D10: SQL | E10: SQL-запрос фильтрует строки до группировки, SQL-запрос фильтрует группы после | F10: — | G10: 0.61563105 | H10: ★ String, ★ группировки, группы, фильтрует | I10: ★ агрегатам, помещать, условия | J10: SQL-запрос, String | K10: 5.5043297 | L10: 7.6844724 | M10: 10 | N10: 9.2193333 | O10: =ROUND(AVERAGE(K10:N10),2) -> 8.1 | P10: Итог: ответ достаточный — ключевые понятия названы
A11: 10 | B11: Чем отличаются GET, POST, PUT и DELETE? | C11: Стажёр | D11: HTTP | E11: ну HTTP-метод получает представление ресурса и должен быть безопасным; HTTP-метод обычно создаёт подресурс или запускает обработку; HTTP-метод заменяет представление ресурса по URI и идемпотентен по семантике; DELETE удаляет ресурс и идемпотентен по семантике, хотя ответы могут различаться. | F11: — | G11: 1 | H11: ★ идемпотентность, ★ подресурс, ★ uri, ★ представление, ★ семантике, получается, удаляет, различаться, заменяет, ответы … и ещё 2 (см. лист «Понятия») | I11: — | J11: HTTP-метод, идемпотентность, SQL-запрос | K11: 9.6276596 | L11: 9.5 | M11: 10 | N11: 7.2056667 | O11: =ROUND(AVERAGE(K11:N11),2) -> 9.08 | P11: Итог: ответ достаточный — ключевые понятия названы; долго начинал отвечать (9.9 с)
A12: 11 | B12: Что такое unit-тест? | C12: Стажёр | D12: Тестирование | E12: ну Unit-тест проверяет небольшую единицу поведения изолированно и быстро. Зависимости часто заменяют тестовыми двойниками. Тест должен быть детерминированным, понятным и проверять поведение, а не внутренние детали реализации. | F12: — | G12: 1 | H12: ★ единицу, ★ двойниками, ★ понятным, ★ небольшую, ★ быстро, тестовыми, детерминированным, детали, изолированно, внутренние … и ещё 2 (см. лист «Понятия») | I12: — | J12: unit-тест | K12: 9.5 | L12: 9.2857143 | M12: 4.0892857 | N12: 9.594 | O12: =ROUND(AVERAGE(K12:N12),2) -> 8.12 | P12: Итог: ответ достаточный — ключевые понятия названы
A13: 12 | B13: Для чего нужны commit, branch и merge? | C13: Стажёр | D13: Git | E13: Commit фиксирует набор изменений в истории; branch позволяет вести независимую | F13: Уточнение 1: Как разрешить конфликт слияния и проверить результат? → линию разработки; merge объединяет истории веток и может потребовать разрешения конфликтов. | G13: 1 | H13: ★ конфликт слияния, ★ истории, ★ набор, ★ линию, ★ веток, разрешения, разработки, фиксирует, вести, объединение … и ещё 1 (см. лист «Понятия») | I13: — | J13: commit, branch, merge, конфликт слияния | K13: 9.25 | L13: 10 | M13: 10 | N13: 9.3641667 | O13: =ROUND(AVERAGE(K13:N13),2) -> 9.65 | P13: Итог: ответ достаточный — ключевые понятия названы; уточняющих вопросов: 1
... A51: 50 | B51: Как действовать при production-инциденте с ростом 5xx и latency? | C51: Senior | D51: Инциденты | E51: ну Подтвердить влияние по SLA/SLO и определить начало/масштаб. Назначить ответственных, проверить недавние релизы и зависимости, стабилизировать систему безопасным rollback или ограничением нагрузки, сохранить диагностические данные. После восстановления провести blameless postmortem с хронологией, корневыми факторами, конкретными владельцами действий и проверкой их эффективности. | F51: — | G51: 1 | H51: ★ blameless, ★ SLA/SLO, ★ релиз, ★ масштабирование, ★ rollback, ★ начало, ★ назначить, ★ ответственных, недавние, провести … и ещё 8 (см. лист «Понятия») | I51: — | J51: SLA/SLO, масштабирование, rollback, blameless, релиз (сленг) | K51: 9.4545455 | L51: 9.5348837 | M51: 10 | N51: 7.2443333 | O51: =ROUND(AVERAGE(K51:N51),2) -> 9.06 | P51: Итог: ответ достаточный — ключевые понятия названы; долго начинал отвечать (9.8 с)

Sheet Диалог
A1: Время | B1: Кто | C1: Тип | D1: Текст | E1: Слов | F1: До начала речи, с | G1: Речь, с | H1: Темп, слов/мин | I1: Источник текста | J1: Покрытие после ответа | K1: Решение системы
A2: 04:30:47 | B2: Интервьюер | C2: Вопрос 1 | D2: Что такое JVM, JRE и JDK?
A3: 04:55:47 | B3: Кандидат | C3: Ответ | D3: ну JVM — виртуальная машина, исполняющая байткод Java. JRE — среда для запуска приложений (JVM и библиотеки выполнения; в современных поставках JDK отдельный JRE обычно не распространяется). JDK включает инструменты разработки, в том числе компилятор javac, и среду выполнения. | E3: 36 | F3: 6.236 | G3: 20.046 | H3: 108 | I3: Vosk (быстрый) | J3: 1 | K3: → следующий вопрос: ответ достаточный — ключевые понятия названы
A4: 04:55:47 | B4: Интервьюер | C4: Вопрос 2 | D4: Чем отличаются примитивные типы от ссылочных?
A5: 04:55:47 | B5: Кандидат | C5: Ответ | D5: Примитивные переменные хранят значения примитивного типа, например int или boolean. Ссылочные переменные содержат ссылку на объект | E5: 16 | F5: 8.485 | G5: 6.304 | H5: 152 | I5: Vosk (быстрый) | J5: 0.396837 | K5: → уточняющий вопрос: не хватало деталей — задан уточняющий вопрос
A6: 04:55:47 | B6: Интервьюер | C6: Уточнение 1 | D6: Что произойдёт при распаковке null из Integer?
A7: 04:55:47 | B7: Кандидат | C7: Ответ | D7: либо null. Объекты создаются в куче в рамках модели памяти JVM; детали размещения могут оптимизироваться JVM. | E7: 16 | F7: 9.38 | G7: 5.664 | H7: 169 | I7: Vosk (быстрый) | J7: 1 | K7: → следующий вопрос: ответ достаточный — ключевые понятия названы
A8: 04:55:47 | B8: Интервьюер | C8: Вопрос 3 | D8: Назовите четыре основных принципа ООП.
A9: 04:55:47 | B9: Кандидат | C9: Ответ | D9: ну не знаю вроде как бы | E9: 6 | F9: 6.968 | G9: 2.994 | H9: 120 | I9: Vosk (быстрый) | J9: 0 | K9: → следующий вопрос: кандидат сказал, что не знает — не давили
A10: 04:55:47 | B10: Интервьюер | C10: Вопрос 4 | D10: Чем отличаются == и equals()?
A11: 04:55:47 | B11: Кандидат | C11: Ответ | D11: Для примитивов == сравнивает значения. Для ссылок == проверяет идентичность ссылок, то | E11: 10 | F11: 6.85 | G11: 4.608 | H11: 130 | I11: Vosk (быстрый) | J11: 0.39350218 | K11: → уточняющий вопрос: не хватало деталей — задан уточняющий вопрос
A12: 04:55:47 | B12: Интервьюер | C12: Уточнение 1 | D12: Что будет с equals() у String и почему строки сравнивают именно так?
A13: 04:55:47 | B13: Кандидат | C13: Ответ | D13: на один объект. equals() сравнивает логическое равенство согласно реализации Object.equals() по умолчанию эквивалентен сравнению ссылок. | E13: 16 | F13: 2.2 | G13: 8.992 | H13: 107 | I13: Vosk (быстрый) | J13: 0.95391534 | K13: → следующий вопрос: ответ достаточный — ключевые понятия названы
A14: 04:55:47 | B14: Интервьюер | C14: Вопрос 5 | D14: Чем отличаются List, Set и Map?
A15: 04:55:47 | B15: Кандидат | C15: Ответ | D15: ну List хранит упорядоченную последовательность и допускает дубликаты; Set моделирует множество уникальных элементов; Map хранит пары ключ-значение с уникальными ключами. Map не является подтипом Collection. | E15: 26 | F15: 7.708 | G15: 12.775 | H15: 122 | I15: Vosk (быстрый) | J15: 1 | K15: → следующий вопрос: ответ достаточный — ключевые понятия названы
A16: 04:55:47 | B16: Интервьюер | C16: Вопрос 6 | D16: Чем checked-исключения отличаются от unchecked?
A17: 04:55:47 | B17: Кандидат | C17: Ответ | D17: ну Checked-исключения должны быть обработаны или объявлены в throws на этапе компиляции. RuntimeException и её подклассы — unchecked; компилятор не требует их явно обрабатывать. Выбор зависит от контракта API и возможности вызывающего кода восстановиться. | E17: 34 | F17: 2.495 | G17: 17.408 | H17: 117 | I17: Vosk (быстрый) | J17: 0.93272016 | K17: → следующий вопрос: ответ достаточный — ключевые понятия названы
A18: 04:55:47 | B18: Интервьюер | C18: Вопрос 7 | D18: Для чего нужны static, final и finally?
A19: 04:55:47 | B19: Кандидат | C19: Ответ | D19: static относится к члену класса, а не конкретному экземпляру; final запрещает повторное присваивание переменной, переопределение метода или наследование класса | E19: 19 | F19: 9.961 | G19: 11.172 | H19: 102 | I19: Vosk (быстрый) | J19: 0.6251602 | K19: → следующий вопрос: ответ достаточный — ключевые понятия названы
A20: 04:55:47 | B20: Интервьюер | C20: Вопрос 8 | D20: Что такое первичный и внешний ключ?
A21: 04:55:47 | B21: Кандидат | C21: Ответ | D21: ну не знаю вроде как бы | E21: 6 | F21: 9.307 | G21: 2.5 | H21: 144 | I21: Vosk (быстрый) | J21: 0 | K21: → следующий вопрос: кандидат сказал, что не знает — не давили
A22: 04:55:47 | B22: Интервьюер | C22: Вопрос 9 | D22: Чем отличаются WHERE и HAVING?
A23: 04:55:47 | B23: Кандидат | C23: Ответ | D23: SQL-запрос фильтрует строки до группировки, SQL-запрос фильтрует группы после | E23: 11 | F23: 3.842 | G23: 4.716 | H23: 140 | I23: Vosk (быстрый) | J23: 0.61563105 | K23: → следующий вопрос: ответ достаточный — ключевые понятия названы
A24: 04:55:47 | B24: Интервьюер | C24: Вопрос 10 | D24: Чем отличаются GET, POST, PUT и DELETE?
A25: 04:55:47 | B25: Кандидат | C25: Ответ | D25: ну HTTP-метод получает представление ресурса и должен быть безопасным; HTTP-метод обычно создаёт подресурс или запускает обработку; HTTP-метод заменяет представление ресурса по URI и идемпотентен по семантике; DELETE удаляет ресурс и идемпотентен по семантике, хотя ответы могут различаться. | E25: 40 | F25: 9.883 | G25: 14.837 | H25: 162 | I25: Vosk (быстрый) | J25: 1 | K25: → следующий вопрос: ответ достаточный — ключевые понятия названы
A26: 04:55:47 | B26: Интервьюер | C26: Вопрос 11 | D26: Что такое unit-тест?
A27: 04:55:47 | B27: Кандидат | C27: Ответ | D27: ну Unit-тест проверяет небольшую единицу поведения изолированно и быстро. Зависимости часто заменяют тестовыми двойниками. Тест должен быть детерминированным, понятным и проверять поведение, а не внутренние детали реализации. | E27: 28 | F27: 2.718 | G27: 9.558 | H27: 176 | I27: Vosk (быстрый) | J27: 1 | K27: → следующий вопрос: ответ достаточный — ключевые понятия названы
A28: 04:55:47 | B28: Интервьюер | C28: Вопрос 12 | D28: Для чего нужны commit, branch и merge?
A29: 04:55:47 | B29: Кандидат | C29: Ответ | D29: Commit фиксирует набор изменений в истории; branch позволяет вести независимую | E29: 10 | F29: 2.239 | G29: 5 | H29: 120 | I29: Vosk (быстрый) | J29: 0.39323144 | K29: → уточняющий вопрос: не хватало деталей — задан уточняющий вопрос
A30: 04:55:47 | B30: Интервьюер | C30: Уточнение 1 | D30: Как разрешить конфликт слияния и проверить результат?
A31: 04:55:47 | B31: Кандидат | C31: Ответ | D31: линию разработки; merge объединяет истории веток и может потребовать разрешения конфликтов. | E31: 11 | F31: 4.576 | G31: 4.521 | H31: 146 | I31: Vosk (быстрый) | J31: 1 | K31: → следующий вопрос: ответ достаточный — ключевые понятия названы
A32: 04:55:47 | B32: Интервьюер | C32: Вопрос 13 | D32: Каков контракт equals() и hashCode()?
A33: 04:55:47 | B33: Кандидат | C33: Ответ | D33: ну не знаю вроде как бы | E33: 6 | F33: 1.123 | G33: 2.538 | H33: 142 | I33: Vosk (быстрый) | J33: 0 | K33: → следующий вопрос: кандидат сказал, что не знает — не давили
A34: 04:55:47 | B34: Интервьюер | C34: Вопрос 14 | D34: Как в общих чертах работает HashMap?
A35: 04:55:47 | B35: Кандидат | C35: Ответ | D35: HashMap вычисляет хеш ключа, по нему выбирает корзину, а при коллизиях различает ключи | E35: 13 | F35: 4.679 | G35: 6.383 | H35: 122 | I35: Vosk (быстрый) | J35: 0.40601531 | K35: → уточняющий вопрос: не хватало деталей — задан уточняющий вопрос
A36: 04:55:47 | B36: Интервьюер | C36: Уточнение 1 | D36: Почему ключи HashMap должны иметь стабильные equals() и hashCode()?
A37: 04:55:47 | B37: Кандидат | C37: Ответ | D37: В современных реализациях Java при определённых условиях длинные цепочки могут преобразовываться в деревья. Порядок обхода не гарантирован. | E37: 17 | F37: 6.535 | G37: 10.064 | H37: 101 | I37: Vosk (быстрый) | J37: 0.77237373 | K37: → следующий вопрос: ответ достаточный — ключевые понятия названы
A38: 04:55:47 | B38: Интервьюер | C38: Вопрос 15 | D38: Зачем нужны generics и что означает type erasure?
A39: 04:55:47 | B39: Кандидат | C39: Ответ | D39: ну Generics обеспечивают проверку типов на этапе компиляции и уменьшают необходимость явных приведений. В Java типовые параметры в основном стираются при компиляции, поэтому нельзя, например, напрямую создать new T() или проверить obj instanceof List<String> обычным способом. | E39: 37 | F39: 9.818 | G39: 12.816 | H39: 173 | I39: Vosk (быстрый) | J39: 1 | K39: → следующий вопрос: ответ достаточный — ключевые понятия названы
A40: 04:55:47 | B40: Интервьюер | C40: Вопрос 16 | D40: Чем интерфейс отличается от абстрактного класса?
...

Sheet Понятия
A1: № | B1: Тема | C1: Ключевое понятие | D1: Вес | E1: Ядро | F1: Прозвучало
A2: 1 | B2: Java Core | C2: javac | D2: 6.290921 | E2: Да | F2: Да
A3: 1 | B3: Java Core | C3: байткод | D3: 6.290921 | E3: Да | F3: Да
A4: 1 | B4: Java Core | C4: среда | D4: 1.9659128 | E4: Да | F4: Да
A5: 1 | B5: Java Core | C5: библиотеки | D5: 1.9659128 | E5: Да | F5: Да
A6: 1 | B6: Java Core | C6: поставках | D6: 1.9659128 | E6: Да | F6: Да
A7: 1 | B7: Java Core | C7: распространяется | D7: 1.9659128 | E7: Да | F7: Да
A8: 1 | B8: Java Core | C8: включает | D8: 1.9659128 | E8: Да | F8: Да
A9: 1 | B9: Java Core | C9: исполняющая | D9: 1.6290483 | E9: Да | F9: Да
A10: 1 | B10: Java Core | C10: современных | D10: 1.6290483 | E10: Нет | F10: Да
A11: 1 | B11: Java Core | C11: разработки | D11: 1.6290483 | E11: Нет | F11: Да
A12: 1 | B12: Java Core | C12: инструменты | D12: 1.4358398 | E12: Нет | F12: Да
A13: 1 | B13: Java Core | C13: числе | D13: 1.4358398 | E13: Нет | F13: Да
... A763: 50 | B763: Инциденты | C763: систему | D763: 1.4358398 | E763: Нет | F763: Да

Sheet Эталоны
A1: № | B1: Уровень | C1: Тема | D1: Вопрос | E1: Эталонный ответ | F1: Критерии из банка вопросов | G1: Уточняющие вопросы (✓ — задавался)
A2: 1 | B2: Стажёр | C2: Java Core | D2: Что такое JVM, JRE и JDK? | E2: JVM — виртуальная машина, исполняющая байткод Java. JRE — среда для запуска приложений (JVM и библиотеки выполнения; в современных поставках JDK отдельный JRE обычно не распространяется). JDK включает инструменты разработки, в том числе компилятор javac, и среду выполнения. | F2: Проверяет базовое понимание платформы Java. | G2: 1. Назвать роль javac и объяснить, что происходит после компиляции. 2. Что именно делает компилятор javac и какой файл получается на выходе? 3. Как JVM исполняет байткод и какую роль играет JIT-компиляция? 4. Почему наличие JDK не означает, что приложение обязательно запускается именно средствами JDK? 5. Как проверить версию Java, которой приложение компилируется и запускается?
A3: 2 | B3: Стажёр | C3: Java Core | D3: Чем отличаются примитивные типы от ссылочных? | E3: Примитивные переменные хранят значения примитивного типа, например int или boolean. Ссылочные переменные содержат ссылку на объект либо null. Объекты создаются в куче в рамках модели памяти JVM; детали размещения могут оптимизироваться JVM. | F3: Не требовать упрощённого утверждения, что все значения всегда лежат только в стеке или куче. | G3: 1. Сравнить int и Integer, обсудить boxing/unboxing. 2. Какие примитивные типы есть в Java и каковы их размеры или диапазоны? 3. Что такое boxing и unboxing и какие проблемы могут возникнуть при сравнении Integer через ==? ✓ 4. Что произойдёт при распаковке null из Integer? 5. Что означает null для ссылочной переменной и как избежать NullPointerException?
A4: 3 | B4: Стажёр | C4: ООП | D4: Назовите четыре основных принципа ООП. | E4: Инкапсуляция — объединение состояния и поведения с контролем доступа; абстракция — выделение существенных свойств; наследование — создание типа на основе другого; полиморфизм — единый интерфейс для разных реализаций. | F4: Ожидаются определения и простой пример хотя бы для двух принципов. | G4: 1. Попросить привести пример полиморфизма из Java. 2. Приведите пример инкапсуляции в классе банковского счёта. 3. Чем композиция отличается от наследования и когда предпочтительнее композиция? 4. Что такое перегрузка и переопределение методов? 5. Как полиморфизм помогает добавлять новые реализации без изменения клиентского кода?
A5: 4 | B5: Стажёр | C5: Java Core | D5: Чем отличаются == и equals()? | E5: Для примитивов == сравнивает значения. Для ссылок == проверяет идентичность ссылок, то есть указывают ли они на один объект. equals() сравнивает логическое равенство согласно реализации класса; Object.equals() по умолчанию эквивалентен сравнению ссылок. | F5: Уточнить контракт equals/hashCode и типичные ошибки переопределения. | G5: ✓ 1. Что будет с equals() у String и почему строки сравнивают именно так? 2. Почему строки обычно сравнивают через equals(), а не через ==? 3. Какие правила необходимо соблюдать при переопределении equals()? 4. Почему при переопределении equals() обычно нужно переопределить и hashCode()? 5. Что такое симметричность и транзитивность в контракте equals()?
A6: 5 | B6: Стажёр | C6: Коллекции | D6: Чем отличаются List, Set и Map? | E6: List хранит упорядоченную последовательность и допускает дубликаты; Set моделирует множество уникальных элементов; Map хранит пары ключ-значение с уникальными ключами. Map не является подтипом Collection. | F6: Кандидат должен подобрать простые сценарии использования. | G6: 1. Попросить выбрать структуру для корзины покупок и справочника пользователей. 2. В каких случаях вы выберете ArrayList, LinkedList, HashSet, TreeSet или HashMap? 3. Гарантирует ли HashMap порядок элементов? Чем отличаются LinkedHashMap и TreeMap? 4. Как коллекции ведут себя при добавлении дубликатов или null? 5. Какие риски возникают при изменении объекта, который хранится в HashSet или используется ключом Map?
A7: 6 | B7: Стажёр | C7: Исключения | D7: Чем checked-исключения отличаются от unchecked? | E7: Checked-исключения должны быть обработаны или объявлены в throws на этапе компиляции. RuntimeException и её подклассы — unchecked; компилятор не требует их явно обрабатывать. Выбор зависит от контракта API и возможности вызывающего кода восстановиться. | F7: Не сводить ответ к правилу «checked всегда хорошие, unchecked всегда плохие». | G7: 1. Когда уместно обернуть исключение в доменное? 2. Когда checked-исключение полезно, а когда оно создаёт лишнюю связанность? 3. Почему не стоит перехватывать Exception и ничего не делать? 4. Чем throw отличается от throws? 5. Как сохранить исходную причину ошибки при оборачивании исключения?
A8: 7 | B8: Стажёр | C8: Java Core | D8: Для чего нужны static, final и finally? | E8: static относится к члену класса, а не конкретному экземпляру; final запрещает повторное присваивание переменной, переопределение метода или наследование класса — в зависимости от применения; finally — блок, обычно используемый для завершающих действий после try/catch. Для ресурсов предпочтительнее try-with-resources. | F8: Различать три похожих по написанию, но разных понятия. | G8: 1. Чем finally отличается от try-with-resources? 2. Может ли final-ссылка указывать на объект, состояние которого меняется? 3. Чем static-поле отличается от поля экземпляра при многопоточном доступе? 4. В каких ситуациях finally может не выполниться? 5. Почему для закрытия файлов и соединений обычно предпочитают try-with-resources?
A9: 8 | B9: Стажёр | C9: SQL | D9: Что такое первичный и внешний ключ? | E9: PRIMARY KEY однозначно идентифицирует строку и не допускает NULL. FOREIGN KEY задаёт ссылочную связь с ключом другой или той же таблицы и помогает поддерживать целостность данных. | F9: Проверить понимание связей и ограничений целостности. | G9: 1. Как моделировать связь многие-ко-многим? 2. Может ли таблица иметь несколько внешних ключей и составной первичный ключ? 3. Какие действия ON DELETE и ON UPDATE бывают у внешнего ключа? 4. Чем UNIQUE отличается от PRIMARY KEY? 5. Как реализовать связь многие-ко-многим и обеспечить уникальность пары?
A10: 9 | B10: Стажёр | C10: SQL | D10: Чем отличаются WHERE и HAVING? | E10: WHERE фильтрует строки до группировки, HAVING фильтрует группы после GROUP BY и обычно применяется к агрегатам. Условия без агрегатов часто лучше помещать в WHERE. | F10: Попросить объяснить порядок обработки запроса концептуально. | G10: 1. Написать запрос количества заказов по клиентам с более чем тремя заказами. 2. В каком порядке логически выполняются FROM, WHERE, GROUP BY, HAVING и SELECT? 3. Можно ли использовать агрегатную функцию в WHERE и почему? 4. Напишите запрос, который выбирает клиентов более чем с тремя заказами. 5. Как NULL влияет на фильтрацию и агрегатные функции?
A11: 10 | B11: Стажёр | C11: HTTP | D11: Чем отличаются GET, POST, PUT и DELETE? | E11: GET получает представление ресурса и должен быть безопасным; POST обычно создаёт подресурс или запускает обработку; PUT заменяет представление ресурса по URI и идемпотентен по семантике; DELETE удаляет ресурс и идемпотентен по семантике, хотя ответы могут различаться. | F11: Оценивать понимание семантики, а не только мнемонику CRUD. | G11: 1. Чем PUT отличается от PATCH? 2. Что означает идемпотентность и какие из этих методов обычно идемпотентны по семантике? 3. Какой HTTP-код вернёте при успешном создании ресурса и почему? 4. Почему GET не должен менять состояние сервера?
A12: 11 | B12: Стажёр | C12: Тестирование | D12: Что такое unit-тест? | E12: Unit-тест проверяет небольшую единицу поведения изолированно и быстро. Зависимости часто заменяют тестовыми двойниками. Тест должен быть детерминированным, понятным и проверять поведение, а не внутренние детали реализации. | F12: Различать unit-, интеграционные и end-to-end тесты. | G12: 1. Какие сценарии покрыть для метода расчёта скидки? 2. Чем unit-тест отличается от интеграционного и end-to-end теста? 3. Что такое тестовый двойник, mock и stub? 4. Как тестировать граничные значения и исключительные сценарии? 5. Какие признаки указывают на нестабильный (flaky) тест?
A13: 12 | B13: Стажёр | C13: Git | D13: Для чего нужны commit, branch и merge? | E13: Commit фиксирует набор изменений в истории; branch позволяет вести независимую линию разработки; merge объединяет истории веток и может потребовать разрешения конфликтов. | F13: Кандидат должен понимать базовый командный workflow. | G13: 1. Что делать при конфликте слияния? 2. Чем merge отличается от rebase? ✓ 3. Как разрешить конфликт слияния и проверить результат? 4. Что делает git cherry-pick и когда его стоит применять? 5. Как безопасно отменить уже опубликованный commit в общей ветке?
... A51: 50 | B51: Senior | C51: Инциденты | D51: Как действовать при production-инциденте с ростом 5xx и latency? | E51: Подтвердить влияние по SLI/SLO и определить начало/масштаб. Назначить ответственных, проверить недавние релизы и зависимости, стабилизировать систему безопасным rollback или ограничением нагрузки, сохранить диагностические данные. После восстановления провести blameless postmortem с хронологией, корневыми факторами, конкретными владельцами действий и проверкой их эффективности. | F51: Оценивается управление инцидентом, приоритизация восстановления и культура обучения. | G51: 1. Какие решения принимать, если rollback тоже рискован? 2. Какие первые метрики и изменения проверите, чтобы оценить масштаб и начало инцидента? 3. Когда безопаснее rollback, feature flag, ограничение нагрузки или отключение зависимости? 4. Как сохранять диагностические данные, не задерживая восстановление сервиса? 5. Как провести blameless postmortem и превратить выводы в проверяемые действия?

Sheet Методика
A1: Как читать отчёт и как считаются оценки
A3: Общий принцип | B3: Каждый ответ сравнивается с эталоном из банка вопросов: ищутся ключевые понятия эталона (термины и значимые слова, взвешенные по редкости) и их синонимы из словаря. Оценка лексическая — она не проверяет, что сказанное верно.
A4: Шкала | B4: Каждый критерий — от 0 до 10. Итог = (критерий 1 + 2 + 3 + 4) / 4, то есть сумма четырёх критериев, нормированная к максимуму 10, округление до 0,01. На листе «Сводка» это формулы над листом «Вопросы».
A5: 1. Развёрнутость и полнота | B5: 10 × (0,75 × покрытие эталона + 0,25 × длина ответа относительно целевой). Покрытие — доля (по весу) ключевых понятий эталона, которые прозвучали в ответе и в уточнениях.
A6: 2. Техническая грамотность | B6: 10 × (0,6 × покрытие «ядра» понятий + 0,25 × доля технических слов по теме вопроса + 0,15 × покрытие) × (1 − штраф за слова-паразиты и неуверенные обороты, до 40 %).
A7: 3. IT-термины и сленг | B7: По вопросу: 10 × (0,55 × разнообразие терминов относительно ожидаемого + 0,45 × плотность терминов на 100 слов, цель 12). По интервью: 80 % среднего + 20 % за разнообразие сленга (цель — 3 разных слова: деплой, прод, баг, рефакторинг...).
A8: 4. Скорость ответа | B8: 0,6 × быстрота начала ответа (до 1,5 с — без штрафа, к 19,5 с оценка падает до нуля) + 0,4 × темп речи (90–180 слов/мин — идеально). Умножается на коэффициент содержательности (0,3–1), чтобы быстрый «не знаю» не давал баллов.
A9: Решение «уточнить / дальше» | B9: Уточнение задаётся, если покрытие ниже порога уровня, лимит уточнений не исчерпан, кандидат не сказал «не знаю» и уточнение выбирается из банка так, чтобы бить в ещё не названные понятия.
A10: Столбцы «Прозвучало / Не прозвучало» | B10: Ключевые понятия эталона; ★ — «ядро» (самые весомые). Подробно по каждому понятию — лист «Понятия» (с фильтром).
A11: Источник текста | B11: Vosk (быстрый) — промежуточное распознавание, по нему принято решение; Vosk — финальный текст; Whisper — второй, более точный проход (если включён). В итоговой оценке используется самый точный из доступных.
A12: Ограничения | B12: Парафраз и редкие синонимы могут быть недооценены; ошибки в формулировках не обнаруживаются; английские термины Vosk слышит неточно (частично исправляется автоматически). Автоматическая оценка — подсказка, а не вердикт.
A14: Пороги достаточности ответа по уровням
A15: Стажёр | B15: ответ достаточный при покрытии эталона от 40 %
A16: Junior | B16: ответ достаточный при покрытии эталона от 45 %
A17: Middle | B17: ответ достаточный при покрытии эталона от 50 %
A18: Senior | B18: ответ достаточный при покрытии эталона от 55 %
A20: Настройки этого интервью
A21: Распознавание речи | B21: Vosk ru-0.42 (потоковое)
A22: Порог тишины (конец ответа) | B22: 450 мс
A23: Макс. уточняющих вопросов на вопрос | B23: 2
A24: Второй проход (Whisper) | B24: выключен
